from django import forms
from django.contrib.auth.models import User
from django.core.exceptions import ValidationError


class SignUpForm(forms.Form):
    username = forms.CharField(max_length=100, required=True, label='Username')
    password = forms.CharField(max_length=100, required=True, label='Password',
                               widget=forms.PasswordInput)
    password_confirm = forms.CharField(max_length=100, required=True,
                                       label="Password confirm", widget=forms.PasswordInput)

    def clean_username(self):
        username = self.cleaned_data.get('username')
        try:
            User.objects.get(username=username)
            raise ValidationError('Username is already taken.', code='username_taken')
        except User.DoesNotExist:
            return username

    def clean(self):
        super().clean()
        password_1 = self.cleaned_data.get('password')
        password_2 = self.cleaned_data.get('password_confirm')
        if password_1 != password_2:
            raise ValidationError('Passwords do not match', code='passwords_do_not_match')
        return self.cleaned_data



